Workbook

Sheet Banks
A1: Bank Code | B1: Bank Name
B2: 2013 | C2: 2014 | D2: 2015 | E2: 2016 | F2: 2017 | G2: 2018 | H2: 2019 | I2: 2020 | J2: 2021 | K2: 2022 | L2: 2023 | M2: 2024
A3: 1 | B3: ABC Bank | C3: ABC Bank | D3: ABC Bank | E3: ABC Bank | F3: ABC Bank | G3: ABC Bank | H3: ABC Bank | I3: ABC Bank | J3: ABC Bank | L3: ABC Bank | M3: ABC Bank
A4: 2 | B4: Bank Of Africa Kenya Ltd | C4: Bank Of Africa Kenya Ltd | D4: Bank Of Africa Kenya Ltd | E4: Bank Of Africa Kenya Ltd | F4: Bank Of Africa Kenya Ltd | G4: Bank Of Africa Kenya Ltd | H4: Bank Of Africa Kenya Ltd | I4: Bank Of Africa Kenya Ltd | J4: Bank Of Africa Kenya Ltd | L4: Bank Of Africa Kenya Ltd | M4: Bank Of Africa Kenya Ltd
A5: 3 | B5: Bank of Baroda | C5: Bank of Baroda | D5: Bank of Baroda | E5: Bank of Baroda | F5: Bank of Baroda | G5: Bank of Baroda | H5: Bank of Baroda | I5: Bank of Baroda | J5: Bank of Baroda | L5: Bank of Baroda | M5: Bank of Baroda
A6: 4 | B6: Bank of India | C6: Bank of India | D6: Bank of India | E6: Bank of India | F6: Bank of India | G6: Bank of India | H6: Bank of India | I6: Bank of India | J6: Bank of India | L6: Bank of India | M6: Bank of India
A7: 5 | B7: Barclays Bank of Kenya | C7: Barclays Bank of Kenya | D7: Barclays Bank of Kenya | E7: Barclays Bank of Kenya | F7: Barclays Bank of Kenya | G7: Barclays Bank of Kenya | H7: Absa Bank Kenya | I7: Absa Bank Kenya | J7: Absa Bank Kenya | L7: Absa Bank Kenya | M7: Absa Bank Kenya
A8: 6 | B8: CFC Stanbic Bank | C8: CFC Stanbic Bank | D8: CFC Stanbic Bank | E8: Stanbic Bank | F8: Stanbic Bank | G8: Stanbic Bank | H8: Stanbic Bank | I8: Stanbic Bank | J8: Stanbic Bank | L8: Stanbic Bank | M8: Stanbic Bank
A9: 7 | B9: Chase Bank | C9: Chase Bank | D9: Chase Bank | E9: Placed under receivership in April 2016 and later take over by SBM bank in 2018 | F9: Placed under receivership in April 2016 and later take over by SBM bank in 2019 | H9: Chase Bank | I9: Chase Bank | J9: Chase Bank | L9: Chase Bank | M9: Chase Bank
A10: 8 | B10: Citibank | C10: Citibank | D10: Citibank | E10: Citibank | F10: Citibank | G10: Citibank | H10: Citibank | I10: Citibank | J10: Citibank | L10: Citibank | M10: Citibank
A11: 9 | B11: Commercial Bank of Africa | C11: Commercial Bank of Africa | D11: Commercial Bank of Africa | E11: Commercial Bank of Africa | F11: Commercial Bank of Africa | G11: Commercial Bank of Africa | H11: Merged with NIC to form NCBA
A12: 10 | B12: Consolidated Bank of Kenya | C12: Consolidated Bank of Kenya | D12: Consolidated Bank of Kenya | E12: Consolidated Bank of Kenya | F12: Consolidated Bank of Kenya | G12: Consolidated Bank of Kenya | H12: Consolidated Bank of Kenya | I12: Consolidated Bank of Kenya | J12: Consolidated Bank of Kenya | L12: Consolidated Bank of Kenya | M12: Consolidated Bank of Kenya
A13: 11 | B13: Co-operative Bank of Kenya | C13: Co-operative Bank of Kenya | D13: Co-operative Bank of Kenya | E13: Co-operative Bank of Kenya | F13: Co-operative Bank of Kenya | G13: Co-operative Bank of Kenya | H13: Co-operative Bank of Kenya | I13: Co-operative Bank of Kenya | J13: Co-operative Bank of Kenya | L13: Co-operative Bank of Kenya | M13: Co-operative Bank of Kenya
A14: 12 | B14: Credit Bank | C14: Credit Bank | D14: Credit Bank | E14: Credit Bank | F14: Credit Bank | G14: Credit Bank | H14: Credit Bank | I14: Credit Bank | J14: Credit Bank | L14: Credit Bank | M14: Credit Bank
A15: 13 | B15: Development Bank of Kenya | C15: Development Bank of Kenya | D15: Development Bank of Kenya | E15: Development Bank of Kenya | F15: Development Bank of Kenya | G15: Development Bank of Kenya | H15: Development Bank of Kenya | I15: Development Bank of Kenya | J15: Development Bank of Kenya | L15: Development Bank of Kenya | M15: Development Bank of Kenya
A16: 14 | B16: Diamond Trust Bank | C16: Diamond Trust Bank | D16: Diamond Trust Bank | E16: Diamond Trust Bank | F16: Diamond Trust Bank | G16: Diamond Trust Bank | H16: Diamond Trust Bank | I16: Diamond Trust Bank | J16: Diamond Trust Bank | L16: Diamond Trust Bank | M16: Diamond Trust Bank
A17: 15 | B17: Dubai Bank | C17: Dubai Bank | D17: Placed under liquidation in August 2015 | H17: Dubai Bank | I17: Dubai Bank | J17: Dubai Bank | L17: Dubai Bank | M17: Dubai Bank
A18: 16 | B18: EcoBank | C18: EcoBank | D18: EcoBank | E18: EcoBank | F18: EcoBank | G18: EcoBank | H18: EcoBank | I18: EcoBank | J18: EcoBank | L18: EcoBank | M18: EcoBank
A19: 17 | B19: Equatorial Commercial Bank | C19: Equatorial Commercial Bank | D19: Equatorial Commercial Bank | E19: Spire Bank | F19: Spire Bank | G19: Spire Bank | H19: Spire Bank | I19: Spire Bank | J19: Spire Bank | L19: Spire Bank | M19: Spire Bank
A20: 18 | B20: Equity Bank | C20: Equity Bank | D20: Equity Bank | E20: Equity Bank | F20: Equity Bank | G20: Equity Bank | H20: Equity Bank | I20: Equity Bank | J20: Equity Bank | L20: Equity Bank | M20: Equity Bank
A21: 19 | B21: Family Bank Limited | C21: Family Bank Limited | D21: Family Bank Limited | E21: Family Bank Limited | F21: Family Bank Limited | G21: Family Bank Limited | H21: Family Bank Limited | I21: Family Bank Limited | J21: Family Bank Limited | L21: Family Bank Limited | M21: Family Bank Limited
A22: 20 | B22: Fidelity Commercial Bank | C22: Fidelity Commercial Bank | D22: Fidelity Commercial Bank | E22: Put up for acquisition by CBK in 2016 and later acquired by SBM Bank in 2017 | F22: Put up for acquisition by CBK in 2016 and later acquired by SBM Bank in 2018 | G22: Put up for acquisition by CBK in 2016 and later acquired by SBM Bank in 2018 | H22: SBM Bank | I22: SBM Bank | J22: SBM Bank | L22: SBM Bank | M22: SBM Bank
A23: 21 | B23: Fina Bank | C23: GT Bank | D23: GT Bank | E23: GT Bank | F23: GT Bank | G23: GT Bank | H23: GT Bank | I23: GT Bank | J23: GT Bank | L23: GT Bank | M23: GT Bank
A24: 22 | B24: First Community Bank | C24: First Community Bank | D24: First Community Bank | E24: First Community Bank | F24: First Community Bank | G24: First Community Bank | H24: First Community Bank | I24: First Community Bank | J24: First Community Bank | L24: Premier Bank | M24: Premier Bank
A25: 23 | B25: Giro Commercial Bank | C25: Giro Commercial Bank | D25: Giro Commercial Bank | E25: Giro Commercial Bank | F25: Giro Commercial Bank | G25: Acquired by I&M in Feb 2017 and its operations merged with those of I&M | H25: Giro Commercial Bank | I25: Giro Commercial Bank | J25: Giro Commercial Bank | L25: Giro Commercial Bank | M25: Giro Commercial Bank
A26: 24 | B26: Guardian Bank | C26: Guardian Bank | D26: Guardian Bank | E26: Guardian Bank | F26: Guardian Bank | G26: Guardian Bank | H26: Guardian Bank | I26: Guardian Bank | J26: Guardian Bank | L26: Guardian Bank | M26: Guardian Bank
A27: 25 | B27: Gulf African Bank | C27: Gulf African Bank | D27: Gulf African Bank | E27: Gulf African Bank | F27: Gulf African Bank | G27: Gulf African Bank | H27: Gulf African Bank | I27: Gulf African Bank | J27: Gulf African Bank | L27: Gulf African Bank | M27: Gulf African Bank
A28: 26 | B28: Habib A.G.Zurich | C28: Habib A.G.Zurich | D28: Habib A.G.Zurich | E28: Habib A.G.Zurich | F28: Habib A.G.Zurich | G28: Habib A.G.Zurich | H28: Habib A.G.Zurich | I28: Habib A.G.Zurich | J28: Habib A.G.Zurich | L28: Habib A.G.Zurich | M28: Habib A.G.Zurich
A29: 27 | B29: Habib Bank Ltd | C29: Habib Bank Ltd | D29: Habib Bank Ltd | E29: Habib Bank Ltd | F29: Acquired by DTB Kenya in August 2017 | G29: Acquired by DTB Kenya in August 2017 | H29: Habib Bank Ltd | I29: Habib Bank Ltd | J29: Habib Bank Ltd | L29: Habib Bank Ltd | M29: Habib Bank Ltd
... A37: 35 | B37: National Bank of kenya | C37: National Bank of kenya | D37: National Bank of kenya | E37: National Bank of kenya | F37: National Bank of kenya | G37: National Bank of kenya | H37: National Bank of kenya | I37: National Bank of kenya | J37: National Bank of kenya | L37: National Bank of kenya | M37: National Bank of kenya
A38: 36 | B38: NIC Bank | C38: NIC Bank | D38: NIC Bank | E38: NIC Bank | F38: NIC Bank | G38: NIC Bank | H38: Merged with CBA to form NCBA
A39: 37 | B39: Oriental Commercial Bank Limited | C39: Oriental Commercial Bank Limited | D39: Oriental Commercial Bank Limited | E39: M-Oriental Bank Limited | F39: M-Oriental Bank Limited | G39: M-Oriental Bank Limited | H39: M-Oriental Bank Limited | I39: M-Oriental Bank Limited | J39: M-Oriental Bank Limited | L39: M-Oriental Bank Limited | M39: M-Oriental Bank Limited
A40: 38 | B40: Paramount Universal Bank | C40: Paramount Universal Bank | D40: Paramount Universal Bank | E40: Paramount Universal Bank | F40: Paramount Universal Bank | G40: Paramount Universal Bank | H40: Paramount Universal Bank | I40: Paramount Universal Bank | J40: Paramount Universal Bank | L40: Paramount Universal Bank | M40: Paramount Universal Bank
A41: 39 | B41: Prime Bank | C41: Prime Bank | D41: Prime Bank | E41: Prime Bank | F41: Prime Bank | G41: Prime Bank | H41: Prime Bank | I41: Prime Bank | J41: Prime Bank | L41: Prime Bank | M41: Prime Bank
A42: 40 | B42: Standard Chartered Bank | C42: Standard Chartered Bank | D42: Standard Chartered Bank | E42: Standard Chartered Bank | F42: Standard Chartered Bank | G42: Standard Chartered Bank | H42: Standard Chartered Bank | I42: Standard Chartered Bank | J42: Standard Chartered Bank | L42: Standard Chartered Bank | M42: Standard Chartered Bank
A43: 41 | B43: Trans-National Bank | C43: Trans-National Bank | D43: Trans-National Bank | E43: Trans-National Bank | F43: Trans-National Bank | G43: Trans-National Bank | H43: Trans-National Bank | I43: Access Bank | J43: Access Bank | L43: Access Bank | M43: Access Bank
A44: 42 | B44: United Bank for Africa | C44: United Bank for Africa | D44: United Bank for Africa | E44: United Bank for Africa | F44: United Bank for Africa | G44: United Bank for Africa | H44: United Bank for Africa | I44: United Bank for Africa | J44: United Bank for Africa | L44: United Bank for Africa | M44: United Bank for Africa
A45: 43 | B45: Victoria Commercial Bank | C45: Victoria Commercial Bank | D45: Victoria Commercial Bank | E45: Victoria Commercial Bank | F45: Victoria Commercial Bank | G45: Victoria Commercial Bank | H45: Victoria Commercial Bank | I45: Victoria Commercial Bank | J45: Victoria Commercial Bank | L45: Victoria Commercial Bank | M45: Victoria Commercial Bank
A46: 44 | G46: Mayfair Bank | H46: Mayfair Bank | I46: Mayfair Bank | J46: Mayfair Bank | L46: Mayfair Bank - CIB | M46: Mayfair Bank - CIB
A47: 45 | G47: Dubai Islamic Bank | H47: Dubai Islamic Bank | I47: Dubai Islamic Bank | J47: Dubai Islamic Bank | L47: Dubai Islamic Bank | M47: Dubai Islamic Bank
...

Sheet Data for analysis
B1: #
C2: 2014 | U2: 2015 | AS2: 2016 | BQ2: 2017 | CO2: 2018 | DM2: 2019 | EK2: 2020 | FI2: 2021 | GG2: 2022 | HE2: 2023 | IC2: 2024 | JA2: 2025
B3: Bank Name | C3: 41699 | I3: 41791 | O3: 41974 | U3: 42064 | AA3: 42156 | AG3: 42248 | AM3: 42339 | AS3: 42430 | AY3: 42522 | BE3: 42614 | BK3: 42705 | BQ3: 42795 | BW3: 42887 | CC3: 42979 | CI3: 43070 | CO3: 43160 | CU3: 43252 | DA3: 43344 | DG3: 43435 | DM3: 43525 | DS3: 43617 | DY3: 43709 | EE3: 43800 | EK3: 43891 | EQ3: 43983 | EW3: 44075 | FC3: 44166 | FI3: 44256 | FO3: 44348 | FU3: 44440 | GA3: 44531 | GG3: 44621 | GM3: 44713 | GS3: 44805 | GY3: 44896 | HE3: 44986 | HK3: 45078 | HQ3: 45170 | HW3: 45261 | IC3: 45352 | II3: 45444 | IO3: 45536 | IU3: 45627 | JA3: 45717 | JG3: 45809 | JM3: 45901 | JS3: 45992
C4: GDP | D4: Interest rate | E4: Inflation rate | F4: Asset Quality | G4: Mgt Efficiency | H4: ROA | I4: GDP | J4: Interest rate | K4: Inflation rate | L4: Asset Quality | M4: Mgt Efficiency | N4: ROA | O4: GDP | P4: Interest rate | Q4: Inflation rate | R4: Asset Quality | S4: Mgt Efficiency | T4: ROA | U4: GDP | V4: Interest rate | W4: Inflation rate | X4: Asset Quality | Y4: Mgt Efficiency | Z4: ROA | AA4: GDP | AB4: Interest rate | AC4: Inflation rate | AD4: Asset Quality | AE4: Mgt Efficiency | AF4: ROA | AG4: GDP | AH4: Interest rate | AI4: Inflation rate | AJ4: Asset Quality | AK4: Mgt Efficiency | AL4: ROA | AM4: GDP | AN4: Interest rate | AO4: Inflation rate | AP4: Asset Quality | AQ4: Mgt Efficiency | AR4: ROA | AS4: GDP | AT4: Interest rate | AU4: Inflation rate | AV4: Asset Quality | AW4: Mgt Efficiency | AX4: ROA | AY4: GDP | AZ4: Interest rate | BA4: Inflation rate | BB4: Asset Quality | BC4: Mgt Efficiency | BD4: ROA | BE4: GDP | BF4: Interest rate | BG4: Inflation rate | BH4: Asset Quality | BI4: Mgt Efficiency | BJ4: ROA | BK4: GDP | BL4: Interest rate | BM4: Inflation rate | BN4: Asset Quality | BO4: Mgt Efficiency | BP4: ROA | BQ4: GDP | BR4: Interest rate | BS4: Inflation rate | BT4: Asset Quality | BU4: Mgt Efficiency | BV4: ROA | BW4: GDP | BX4: Interest rate | BY4: Inflation rate | BZ4: Asset Quality | CA4: Mgt Efficiency | CB4: ROA | CC4: GDP | CD4: Interest rate | CE4: Inflation rate | CF4: Asset Quality | CG4: Mgt Efficiency | CH4: ROA | CI4: GDP | CJ4: Interest rate | CK4: Inflation rate | CL4: Asset Quality | CM4: Mgt Efficiency | CN4: ROA | CO4: GDP | CP4: Interest rate | CQ4: Inflation rate | CR4: Asset Quality | CS4: Mgt Efficiency | CT4: ROA | CU4: GDP | CV4: Interest rate | CW4: Inflation rate | CX4: Asset Quality | CY4: Mgt Efficiency | CZ4: ROA | DA4: GDP | DB4: Interest rate | DC4: Inflation rate | DD4: Asset Quality | DE4: Mgt Efficiency | DF4: ROA | DG4: GDP | DH4: Interest rate | DI4: Inflation rate | DJ4: Asset Quality | DK4: Mgt Efficiency | DL4: ROA | DM4: GDP | DN4: Interest rate | DO4: Inflation rate | DP4: Asset Quality | DQ4: Mgt Efficiency | DR4: ROA | DS4: GDP | DT4: Interest rate | DU4: Inflation rate | DV4: Asset Quality | DW4: Mgt Efficiency | DX4: ROA | DY4: GDP | DZ4: Interest rate | EA4: Inflation rate | EB4: Asset Quality | EC4: Mgt Efficiency | ED4: ROA | EE4: GDP | EF4: Interest rate | EG4: Inflation rate | EH4: Asset Quality | EI4: Mgt Efficiency | EJ4: ROA | EK4: GDP | EL4: Interest rate | EM4: Inflation rate | EN4: Asset Quality | EO4: Mgt Efficiency | EP4: ROA | EQ4: GDP | ER4: Interest rate | ES4: Inflation rate | ET4: Asset Quality | EU4: Mgt Efficiency | EV4: ROA | EW4: GDP | EX4: Interest rate | EY4: Inflation rate | EZ4: Asset Quality | FA4: Mgt Efficiency | FB4: ROA | FC4: GDP | FD4: Interest rate | FE4: Inflation rate | FF4: Asset Quality | FG4: Mgt Efficiency | FH4: ROA | FI4: GDP | FJ4: Interest rate | FK4: Inflation rate | FL4: Asset Quality | FM4: Mgt Efficiency | FN4: ROA | FO4: GDP | FP4: Interest rate | FQ4: Inflation rate | FR4: Asset Quality | FS4: Mgt Efficiency | FT4: ROA | FU4: GDP | FV4: Interest rate | FW4: Inflation rate | FX4: Asset Quality | FY4: Mgt Efficiency | FZ4: ROA | GA4: GDP | GB4: Interest rate | GC4: Inflation rate | GD4: Asset Quality | GE4: Mgt Efficiency | GF4: ROA | GG4: GDP | GH4: Interest rate | GI4: Inflation rate | GJ4: Asset Quality | GK4: Mgt Efficiency | GL4: ROA | GM4: GDP | GN4: Interest rate | GO4: Inflation rate | GP4: Asset Quality | GQ4: Mgt Efficiency | GR4: ROA | GS4: GDP | GT4: Interest rate | GU4: Inflation rate | GV4: Asset Quality | GW4: Mgt Efficiency | GX4: ROA | GY4: GDP | GZ4: Interest rate | HA4: Inflation rate | HB4: Asset Quality | HC4: Mgt Efficiency | HD4: ROA | HE4: GDP | HF4: Interest rate | HG4: Inflation rate | HH4: Asset Quality | HI4: Mgt Efficiency | HJ4: ROA | HK4: GDP | HL4: Interest rate | HM4: Inflation rate | HN4: Asset Quality | HO4: Mgt Efficiency | HP4: ROA | HQ4: GDP | HR4: Interest rate | HS4: Inflation rate | HT4: Asset Quality | HU4: Mgt Efficiency | HV4: ROA | HW4: GDP | HX4: Interest rate | HY4: Inflation rate | HZ4: Asset Quality | IA4: Mgt Efficiency | IB4: ROA | IC4: GDP | ID4: Interest rate | IE4: Inflation rate | IF4: Asset Quality | IG4: Mgt Efficiency | IH4: ROA | II4: GDP | IJ4: Interest rate | IK4: Inflation rate | IL4: Asset Quality | IM4: Mgt Efficiency | IN4: ROA | IO4: GDP | IP4: Interest rate | IQ4: Inflation rate | IR4: Asset Quality | IS4: Mgt Efficiency | IT4: ROA | IU4: GDP | IV4: Interest rate | IW4: Inflation rate | IX4: Asset Quality | IY4: Mgt Efficiency | IZ4: ROA | JA4: GDP | JB4: Interest rate | JC4: Inflation rate | JD4: Asset Quality | JE4: Mgt Efficiency | JF4: ROA | JG4: GDP | JH4: Interest rate | JI4: Inflation rate | JJ4: Asset Quality | JK4: Mgt Efficiency | JL4: ROA | JM4: GDP | JN4: Interest rate | JO4: Inflation rate | JP4: Asset Quality | JQ4: Mgt Efficiency | JR4: ROA | JS4: GDP | JT4: Interest rate | JU4: Inflation rate | JV4: Asset Quality | JW4: Mgt Efficiency | JX4: ROA
A5: 1 | B5: ABC Bank | C5: 0.052 | D5: 16.91 | E5: 0.0627 | F5: 0.045405928 | G5: 0.69514707 | H5: 0.014665198 | I5: 0.06 | J5: 0.1636 | K5: 0.0739 | L5: 0.067301025 | M5: 0.75249518 | N5: 0.011876546 | O5: 0.05 | P5: 0.1599 | Q5: 0.0602 | R5: 0.049227827 | S5: 0.92101622 | T5: 0.012568498 | U5: 0.057 | V5: 0.1546 | W5: 0.0631 | X5: 0.072964761 | Y5: 0.70283835 | Z5: 0.014215563 | AA5: 0.056 | AB5: 0.1606 | AC5: 0.0703 | AD5: 0.066403973 | AE5: 0.71869931 | AF5: 0.011677502 | AG5: 0.061 | AH5: 0.1682 | AI5: 0.0597 | AJ5: 0.1375945 | AK5: 0.68181462 | AL5: 0.011898201 | AM5: 0.05 | AN5: 0.183 | AO5: 0.0801 | AP5: 0.12730314 | AQ5: 0.95118861 | AR5: 0.012263735 | AS5: 0.038 | AT5: 0.1787 | AU5: 0.0645 | AV5: 0.13915209 | AW5: 0.6836856 | AX5: 0.014290063 | AY5: 0.038 | AZ5: 0.1818 | BA5: 0.058 | BB5: 0.13851823 | BC5: 0.68857683 | BD5: 0.013231178 | BE5: 0.044 | BF5: 0.1386 | BG5: 0.0634 | BH5: 0.14267298 | BI5: 0.72469925 | BJ5: 0.0086487484 | BK5: 0.042 | BL5: 0.1366 | BM5: 0.0635 | BN5: 0.13826028 | BO5: 0.78618419 | BP5: 0.0070709851 | BQ5: 0.054 | BR5: 0.1361 | BS5: 0.1028 | BT5: 0.145888 | BU5: 0.50107294 | BV5: 0.0076268125 | BW5: 0.033 | BX5: 0.1366 | BY5: 0.0921 | BZ5: 0.1630576 | CA5: 0.74811677 | CB5: 0.0024653854 | CC5: 0.032 | CD5: 0.1369 | CE5: 0.0706 | CF5: 0.17252498 | CG5: 0.77380868 | CH5: 0.0060845457 | CI5: 0.038 | CJ5: 0.1364 | CK5: 0.045 | CL5: 0.15874312 | CM5: 0.81737303 | CN5: 0.0058056071 | CO5: 0.052 | CP5: 0.1349 | CQ5: 0.0418 | CR5: 0.17174388 | CS5: 0.81234593 | CT5: 0.0057922888 | CU5: 0.061 | CV5: 0.1322 | CW5: 0.0428 | CX5: 0.17930718 | CY5: 0.76857214 | CZ5: 0.0043080763 | DA5: 0.053 | DB5: 0.1266 | DC5: 0.057 | DD5: 0.17867807 | DE5: 0.81665917 | DF5: 0.0049546095 | DG5: 0.056 | DH5: 0.1251 | DI5: 0.0571 | DJ5: 0.16954524 | DK5: 0.79893866 | DL5: 0.0024144746 | DM5: 0.048 | DN5: 0.1251 | DO5: 0.0435 | DP5: 0.18773631 | DQ5: 0.8674733 | DR5: 0.0032608944 | DS5: 0.06 | DT5: 0.1247 | DU5: 0.057 | DV5: 0.18647538 | DW5: 0.88082873 | DX5: 0.0026124132 | DY5: 0.05 | DZ5: 0.1247 | EA5: 0.0383 | EB5: 0.19126766 | EC5: 0.87180774 | ED5: 0.0023845334 | EE5: 0.051 | EF5: 0.1224 | EG5: 0.0582 | EH5: 0.13085691 | EI5: 0.860361 | EJ5: 0.0042758337 | EK5: 0.046 | EL5: 0.1209 | EM5: 0.0584 | EN5: 0.13139371 | EO5: 0.87497033 | EP5: 0.0034968931 | EQ5: -0.041 | ER5: 0.1189 | ES5: 0.0459 | ET5: 0.12748493 | EU5: 0.87998479 | EV5: 0.0028031363 | EW5: -0.036 | EX5: 0.1175 | EY5: 0.042 | EZ5: 0.12663912 | FA5: 0.87012384 | FB5: 0.0020668948 | FC5: -0.003 | FD5: 0.1202 | FE5: 0.0562 | FF5: 0.11320991 | FG5: 0.82082289 | FH5: 0.0044284159 | FI5: 0.024 | FJ5: 0.1205 | FK5: 0.059 | FL5: 0.11484447 | FM5: 0.87491188 | FN5: 0.0027421819 | FO5: 0.103 | FP5: 0.1202 | FQ5: 0.0632 | FR5: 0.10906695 | FS5: 0.87395909 | FT5: 0.0023150966 | FU5: 0.094 | FV5: 0.121 | FW5: 0.0691 | FX5: 0.10920678 | FY5: 0.88060412 | FZ5: 0.0019425933 | GA5: 0.076 | GB5: 0.1216 | GC5: 0.0573 | GD5: 0.14880928 | GE5: 0.80734621 | GF5: 0.0031455572 | GG5: 0.059 | GH5: 0.1215 | GI5: 0.0556 | GJ5: 0.15040826 | GK5: 0.87302602 | GL5: 0.002561733 | GM5: 0.049 | GN5: 0.1227 | GO5: 0.0791 | GP5: 0.15300356 | GQ5: 0.85590731 | GR5: 0.0021991338 | GS5: 0.046 | GT5: 0.1241 | GU5: 0.0918 | GV5: 0.15578729 | GW5: 0.84648683 | GX5: 0.0021366627 | GY5: 0.049 | GZ5: 0.1267 | HA5: 0.0906 | HB5: 0.15478643 | HC5: 0.79403862 | HD5: 0.0064317379 | HE5: 0.054 | HF5: 0.1309 | HG5: 0.0919 | HH5: 0.15518994 | HI5: 0.85069674 | HJ5: 0.0033349274 | HK5: 0.055 | HL5: 0.1331 | HM5: 0.0788 | HN5: 0.15153975 | HO5: 0.87171191 | HP5: 0.0023473094 | HQ5: 0.06 | HR5: 0.1398 | HS5: 0.0678 | HT5: 0.15020369 | HU5: 0.86683426 | HV5: 0.0021632741 | HW5: 0.056 | HX5: 0.1463 | HY5: 0.0663 | HZ5: 0.12344076 | IA5: 0.7998862 | IB5: 0.0063156477 | IC5: 0.049 | ID5: 0.1628 | IE5: 0.057 | IF5: 0.15069574 | IG5: 0.85384624 | IH5: 0.0030124574 | II5: 0.046 | IJ5: 0.1685 | IK5: 0.0622 | IL5: 0.15425203 | IM5: 0.86312553 | IN5: 0.002124592 | IO5: 0.04 | IP5: 0.1691 | IQ5: 0.0356 | IR5: 0.15524075 | IS5: 0.8682173 | IT5: 0.0019380295 | IU5: 0.047 | IV5: 0.1689 | IW5: 0.0299 | IX5: 0.22867369 | IY5: 0.83869548 | IZ5: -0.0068997193 | JA5: 0.049 | JB5: 0.1577 | JC5: 0.0362 | JD5: 0.2288022 | JE5: 0.8776199 | JF5: 0.0026050696 | JG5: 0.05 | JH5: 0.1528 | JI5: 0.0382 | JJ5: 0.23309382 | JK5: 0.76668245 | JL5: 0.0020553192 | JM5: 0.049 | JN5: 0.1507 | JO5: 0.0458 | JP5: 0.23764501 | JQ5: 0.71645881 | JR5: 0.0017758457 | JS5: 0.05 | JT5: 0.1481 | JU5: 0.0449 | JV5: 0.39309023 | JW5: 0.72501588 | JX5: -0.015733347
A6: 2 | B6: Bank Of Africa Kenya Ltd | C6: 0.052 | D6: 0.1691 | E6: 0.0627 | F6: 0.032327879 | G6: 0.67287873 | H6: 0.01288096 | I6: 0.06 | J6: 0.1636 | K6: 0.0739 | L6: 0.030167236 | M6: 0.69752021 | N6: 0.011153877 | O6: 0.05 | P6: 0.1599 | Q6: 0.0602 | R6: 0.026947056 | S6: 0.81050196 | T6: 0.00250857 | U6: 0.057 | V6: 0.1546 | W6: 0.0631 | X6: 0.027403626 | Y6: 0.8056459 | Z6: 0.0067034203 | AA6: 0.056 | AB6: 0.1606 | AC6: 0.0703 | AD6: 0.058406729 | AE6: 0.79532916 | AF6: 0.001757349 | AG6: 0.061 | AH6: 0.1682 | AI6: 0.0597 | AJ6: 0.059383148 | AK6: 0.75397028 | AL6: 0.0028677766 | AM6: 0.05 | AN6: 0.183 | AO6: 0.0801 | AP6: 0.18863187 | AQ6: 0.80425478 | AR6: -0.015565384 | AS6: 0.038 | AT6: 0.1787 | AU6: 0.0645 | AV6: 0.19032766 | AW6: 0.53845109 | AX6: -0.0051579854 | AY6: 0.038 | AZ6: 0.1818 | BA6: 0.058 | BB6: 0.18647322 | BC6: 0.84566727 | BD6: 0.00049540885 | BE6: 0.044 | BF6: 0.1386 | BG6: 0.0634 | BH6: 0.19306604 | BI6: 0.86493421 | BJ6: -8.1330017e-05 | BK6: 0.042 | BL6: 0.1366 | BM6: 0.0635 | BN6: 0.20670632 | BO6: 0.77138878 | BP6: 0.00016715101 | BQ6: 0.054 | BR6: 0.1361 | BS6: 0.1028 | BT6: 0.19970199 | BU6: 0.69008776 | BV6: 0.00060415343 | BW6: 0.033 | BX6: 0.1366 | BY6: 0.0921 | BZ6: 0.19143232 | CA6: 0.67538568 | CB6: 0.0010957039 | CC6: 0.032 | CD6: 0.1369 | CE6: 0.0706 | CF6: 0.20965511 | CG6: 1.0599959 | CH6: 0.00018122868 | CI6: 0.038 | CJ6: 0.1364 | CK6: 0.045 | CL6: 0.21972985 | CM6: 0.76644888 | CN6: 0.0012273321 | CO6: 0.052 | CP6: 0.1349 | CQ6: 0.0418 | CR6: 0.23679287 | CS6: 0.69758628 | CT6: 0.0013115377 | CU6: 0.061 | CV6: 0.1322 | CW6: 0.0428 | CX6: 0.25175574 | CY6: 0.74675751 | CZ6: 0.002212048 | DA6: 0.053 | DB6: 0.1266 | DC6: 0.057 | DD6: 0.24671314 | DE6: 0.78924885 | DF6: 0.0013391842 | DG6: 0.056 | DH6: 0.1251 | DI6: 0.0571 | DJ6: 0.25280432 | DK6: 0.78837838 | DL6: 0.0033517846 | DM6: 0.048 | DN6: 0.1251 | DO6: 0.0435 | DP6: 0.25031875 | DQ6: 0.79668123 | DR6: 0.002511444 | DS6: 0.06 | DT6: 0.1247 | DU6: 0.057 | DV6: 0.24815695 | DW6: 0.76942149 | DX6: 0.0048012365 | DY6: 0.05 | DZ6: 0.1247 | EA6: 0.0383 | EB6: 0.2387427 | EC6: 0.85364873 | ED6: 0.0028891699 | EE6: 0.051 | EF6: 0.1224 | EG6: 0.0582 | EH6: 0.29273458 | EI6: 1.0827048 | EJ6: -0.043831204 | EK6: 0.046 | EL6: 0.1209 | EM6: 0.0584 | EN6: 0.28133853 | EO6: 1.3772643 | EP6: -0.024944673 | EQ6: -0.041 | ER6: 0.1189 | ES6: 0.0459 | ET6: 0.26775902 | EU6: 0.94072015 | EV6: -0.0075461757 | EW6: -0.036 | EX6: 0.1175 | EY6: 0.042 | EZ6: 0.26340546 | FA6: 0.94924052 | FB6: -0.0064882858 | FC6: -0.003 | FD6: 0.1202 | FE6: 0.0562 | FF6: 0.28508963 | FG6: 1.00056 | FH6: -0.0087881995 | FI6: 0.024 | FJ6: 0.1205 | FK6: 0.059 | FL6: 0.27458928 | FM6: 0.89558897 | FN6: -0.0015253904 | FO6: 0.103 | FP6: 0.1202 | FQ6: 0.0632 | FR6: 0.28520716 | FS6: 0.8960996 | FT6: -0.002690454 | FU6: 0.094 | FV6: 0.121 | FW6: 0.0691 | FX6: 0.28245981 | FY6: 0.84526987 | FZ6: 0.0001440046 | GA6: 0.076 | GB6: 0.1216 | GC6: 0.0573 | GD6: 0.25848905 | GE6: 0.6834473 | GF6: 0.004908419 | GG6: 0.059 | GH6: 0.1215 | GI6: 0.0556 | GJ6: 0.24504571 | GK6: 0.77183874 | GL6: 0.0051673904 | GM6: 0.049 | GN6: 0.1227 | GO6: 0.0791 | GP6: 0.24207486 | GQ6: 0.72783466 | GR6: 0.0058326096 | GS6: 0.046 | GT6: 0.1241 | GU6: 0.0918 | GV6: 0.16872856 | GW6: 0.70948811 | GX6: 0.0047625794 | GY6: 0.049 | GZ6: 0.1267 | HA6: 0.0906 | HB6: 0.16771408 | HC6: 0.70047216 | HD6: 0.0042315346 | HE6: 0.054 | HF6: 0.1309 | HG6: 0.0919 | HH6: 0.1785937 | HI6: 0.60244762 | HJ6: 0.0094465559 | HK6: 0.055 | HL6: 0.1331 | HM6: 0.0788 | HN6: 0.15318046 | HO6: 0.61812362 | HP6: 0.0083125811 | HQ6: 0.06 | HR6: 0.1398 | HS6: 0.0678 | HT6: 0.15372062 | HU6: 0.64081987 | HV6: 0.0061894302 | HW6: 0.056 | HX6: 0.1463 | HY6: 0.0663 | HZ6: 0.15731285 | IA6: 0.65259977 | IB6: 0.005587334 | IC6: 0.049 | ID6: 0.1628 | IE6: 0.057 | IF6: 0.14830829 | IG6: 0.76441373 | IH6: 0.0057358042 | II6: 0.046 | IJ6: 0.1685 | IK6: 0.0622 | IL6: 0.11793666 | IM6: 0.75220846 | IN6: 0.00504826 | IO6: 0.04 | IP6: 0.1691 | IQ6: 0.0356 | IR6: 0.11966432 | IS6: 0.76087805 | IT6: 0.0035882813 | IU6: 0.047 | IV6: 0.1689 | IW6: 0.0299 | IX6: 0.15122875 | IY6: 0.78113087 | IZ6: 0.0021846946 | JA6: 0.049 | JB6: 0.1577 | JC6: 0.0362 | JD6: 0.14411239 | JE6: 0.87505092 | JF6: 0.0016121182 | JG6: 0.05 | JH6: 0.1528 | JI6: 0.0382 | JJ6: 0.13977219 | JK6: 0.84047531 | JL6: 0.0024273585 | JM6: 0.049 | JN6: 0.1507 | JO6: 0.0458 | JP6: 0.12550751 | JQ6: 0.7962092 | JR6: 0.0046963938 | JS6: 0.05 | JT6: 0.1481 | JU6: 0.0449 | JV6: 0.13071812 | JW6: 0.7498566 | JX6: 0.0059916911
A7: 3 | B7: Bank of Baroda | C7: 0.052 | D7: 0.1691 | E7: 0.0627 | F7: 0.021058722 | G7: 0.25646167 | H7: 0.034447597 | I7: 0.06 | J7: 0.1636 | K7: 0.0739 | L7: 0.024344327 | M7: 0.22149916 | N7: 0.035118625 | O7: 0.05 | P7: 0.1599 | Q7: 0.0602 | R7: 0.032244372 | S7: 0.23456884 | T7: 0.038904719 | U7: 0.057 | V7: 0.1546 | W7: 0.0631 | X7: 0.034698387 | Y7: 0.23893924 | Z7: 0.033288373 | AA7: 0.056 | AB7: 0.1606 | AC7: 0.0703 | AD7: 0.033980781 | AE7: 0.21146717 | AF7: 0.034205155 | AG7: 0.061 | AH7: 0.1682 | AI7: 0.0597 | AJ7: 0.059620179 | AK7: 0.23803781 | AL7: 0.027525927 | AM7: 0.05 | AN7: 0.183 | AO7: 0.0801 | AP7: 0.064566793 | AQ7: 0.23726095 | AR7: 0.031141758 | AS7: 0.038 | AT7: 0.1787 | AU7: 0.0645 | AV7: 0.06221127 | AW7: 0.20017036 | AX7: 0.032707596 | AY7: 0.038 | AZ7: 0.1818 | BA7: 0.058 | BB7: 0.088309465 | BC7: 0.20425135 | BD7: 0.036029753 | BE7: 0.044 | BF7: 0.1386 | BG7: 0.0634 | BH7: 0.081388104 | BI7: 0.19986269 | BJ7: 0.035050851 | BK7: 0.042 | BL7: 0.1366 | BM7: 0.0635 | BN7: 0.077964133 | BO7: 0.19608727 | BP7: 0.039007956 | BQ7: 0.054 | BR7: 0.1361 | BS7: 0.1028 | BT7: 0.081637039 | BU7: 0.22313787 | BV7: 0.033322153 | BW7: 0.033 | BX7: 0.1366 | BY7: 0.0921 | BZ7: 0.067305216 | CA7: 0.72574189 | CB7: 0.042473332 | CC7: 0.032 | CD7: 0.1369 | CE7: 0.0706 | CF7: 0.060282907 | CG7: 0.17004285 | CH7: 0.041336309 | CI7: 0.038 | CJ7: 0.1364 | CK7: 0.045 | CL7: 0.055391551 | CM7: 0.17366457 | CN7: 0.043822669 | CO7: 0.052 | CP7: 0.1349 | CQ7: 0.0418 | CR7: 0.07639071 | CS7: 0.21485633 | CT7: 0.033894131 | CU7: 0.061 | CV7: 0.1322 | CW7: 0.0428 | CX7: 0.076227022 | CY7: 0.21447674 | CZ7: 0.031622889 | DA7: 0.053 | DB7: 0.1266 | DC7: 0.057 | DD7: 0.07771036 | DE7: 0.17214961 | DF7: 0.048573557 | DG7: 0.056 | DH7: 0.1251 | DI7: 0.0571 | DJ7: 0.081086687 | DK7: 0.18798401 | DL7: 0.035862585 | DM7: 0.048 | DN7: 0.1251 | DO7: 0.0435 | DP7: 0.08287942 | DQ7: 0.22158971 | DR7: 0.028789412 | DS7: 0.06 | DT7: 0.1247 | DU7: 0.057 | DV7: 0.084065664 | DW7: 0.18291901 | DX7: 0.029141014 | DY7: 0.05 | DZ7: 0.1247 | EA7: 0.0383 | EB7: 0.0804182 | EC7: 0.17956607 | ED7: 0.030887078 | EE7: 0.051 | EF7: 0.1224 | EG7: 0.0582 | EH7: 0.076483247 | EI7: 0.19486251 | EJ7: 0.030735054 | EK7: 0.046 | EL7: 0.1209 | EM7: 0.0584 | EN7: 0.077503868 | EO7: 0.2482057 | EP7: 0.028099564 | EQ7: -0.041 | ER7: 0.1189 | ES7: 0.0459 | ET7: 0.10772167 | EU7: 0.18703355 | EV7: 0.026258817 | EW7: -0.036 | EX7: 0.1175 | EY7: 0.042 | EZ7: 0.1060427 | FA7: 0.16942235 | FB7: 0.027115647 | FC7: -0.003 | FD7: 0.1202 | FE7: 0.0562 | FF7: 0.11193958 | FG7: 0.18666945 | FH7: 0.029648828 | FI7: 0.024 | FJ7: 0.1205 | FK7: 0.059 | FL7: 0.106632 | FM7: 0.20733173 | FN7: 0.0240462 | FO7: 0.103 | FP7: 0.1202 | FQ7: 0.0632 | FR7: 0.117694 | FS7: 0.21569625 | FT7: 0.025220106 | FU7: 0.094 | FV7: 0.121 | FW7: 0.0691 | FX7: 0.10694165 | FY7: 0.19206356 | FZ7: 0.027083967 | GA7: 0.076 | GB7: 0.1216 | GC7: 0.0573 | GD7: 0.095115951 | GE7: 0.19477562 | GF7: 0.030393997 | GG7: 0.059 | GH7: 0.1215 | GI7: 0.0556 | GJ7: 0.096935843 | GK7: 0.21931992 | GL7: 0.0258583 | GM7: 0.049 | GN7: 0.1227 | GO7: 0.0791 | GP7: 0.092520483 | GQ7: 0.18052065 | GR7: 0.026863262 | GS7: 0.046 | GT7: 0.1241 | GU7: 0.0918 | GV7: 0.089668955 | GW7: 0.18491652 | GX7: 0.026756501 | GY7: 0.049 | GZ7: 0.1267 | HA7: 0.0906 | HB7: 0.085880264 | HC7: 0.18512829 | HD7: 0.027831529 | HE7: 0.054 | HF7: 0.1309 | HG7: 0.0919 | HH7: 0.0900765 | HI7: 0.21305322 | HJ7: 0.021716975 | HK7: 0.055 | HL7: 0.1331 | HM7: 0.0788 | HN7: 0.089856569 | HO7: 0.19048199 | HP7: 0.026498352 | HQ7: 0.06 | HR7: 0.1398 | HS7: 0.0678 | HT7: 0.082252807 | HU7: 0.19835116 | HV7: 0.026595827 | HW7: 0.056 | HX7: 0.1463 | HY7: 0.0663 | HZ7: 0.073452687 | IA7: 0.19873036 | IB7: 0.028835824 | IC7: 0.049 | ID7: 0.1628 | IE7: 0.057 | IF7: 0.12617333 | IG7: 0.28255742 | IH7: 0.021978074 | II7: 0.046 | IJ7: 0.1685 | IK7: 0.0622 | IL7: 0.12686083 | IM7: 0.24703613 | IN7: 0.020507023 | IO7: 0.04 | IP7: 0.1691 | IQ7: 0.0356 | IR7: 0.1213054 | IS7: 0.27382971 | IT7: 0.018883269 | IU7: 0.047 | IV7: 0.1689 | IW7: 0.0299 | IX7: 0.10995614 | IY7: 0.29726281 | IZ7: 0.020184042 | JA7: 0.049 | JB7: 0.1577 | JC7: 0.0362 | JD7: 0.11492406 | JE7: 0.25891748 | JF7: 0.022791603 | JG7: 0.05 | JH7: 0.1528 | JI7: 0.0382 | JJ7: 0.11303348 | JK7: 0.22636836 | JL7: 0.024862512 | JM7: 0.049 | JN7: 0.1507 | JO7: 0.0458 | JP7: 0.11262567 | JQ7: 0.2203359 | JR7: 0.026741275 | JS7: 0.05 | JT7: 0.1481 | JU7: 0.0449 | JV7: 0.10923001 | JW7: 0.23115092 | JX7: 0.03155936
A8: 4 | B8: Bank of India | C8: 0.052 | D8: 0.1691 | E8: 0.0627 | F8: 0.0085097743 | G8: 0.39044081 | H8: 0.020452215 | I8: 0.06 | J8: 0.1636 | K8: 0.0739 | L8: 0.0081603867 | M8: 0.29130486 | N8: 0.026117232 | O8: 0.05 | P8: 0.1599 | Q8: 0.0602 | R8: 0.0055611898 | S8: 0.25508891 | T8: 0.031380052 | U8: 0.057 | V8: 0.1546 | W8: 0.0631 | X8: 0.0051136259 | Y8: 0.29889093 | Z8: 0.026957164 | AA8: 0.056 | AB8: 0.1606 | AC8: 0.0703 | AD8: 0.0051341698 | AE8: 0.26075067 | AF8: 0.028360671 | AG8: 0.061 | AH8: 0.1682 | AI8: 0.0597 | AJ8: 0.0050168691 | AK8: 0.25215775 | AL8: 0.029903764 | AM8: 0.05 | AN8: 0.183 | AO8: 0.0801 | AP8: 0.019845835 | AQ8: 0.25245545 | AR8: 0.028953044 | AS8: 0.038 | AT8: 0.1787 | AU8: 0.0645 | AV8: 0.0092053947 | AW8: 0.23481547 | AX8: 0.039694705 | AY8: 0.038 | AZ8: 0.1818 | BA8: 0.058 | BB8: 0.021687728 | BC8: 0.20821251 | BD8: 0.035328383 | BE8: 0.044 | BF8: 0.1386 | BG8: 0.0634 | BH8: 0.014598752 | BI8: 0.20087433 | BJ8: 0.035825875 | BK8: 0.042 | BL8: 0.1366 | BM8: 0.0635 | BN8: 0.013750301 | BO8: 0.18951919 | BP8: 0.036473462 | BQ8: 0.054 | BR8: 0.1361 | BS8: 0.1028 | BT8: 0.011434085 | BU8: 0.18771859 | BV8: 0.037171135 | BW8: 0.033 | BX8: 0.1366 | BY8: 0.0921 | BZ8: 0.023662302 | CA8: 0.178425 | CB8: 0.033858732 | CC8: 0.032 | CD8: 0.1369 | CE8: 0.0706 | CF8: 0.029373642 | CG8: 0.17478793 | CH8: 0.035382189 | CI8: 0.038 | CJ8: 0.1364 | CK8: 0.045 | CL8: 0.020298168 | CM8: 0.17078772 | CN8: 0.039995335 | CO8: 0.052 | CP8: 0.1349 | CQ8: 0.0418 | CR8: 0.023144418 | CS8: 0.19744698 | CT8: 0.034135148 | CU8: 0.061 | CV8: 0.1322 | CW8: 0.0428 | CX8: 0.037821235 | CY8: 0.18087041 | CZ8: 0.030803882 | DA8: 0.053 | DB8: 0.1266 | DC8: 0.057 | DD8: 0.037390917 | DE8: 0.20373459 | DF8: 0.042444594 | DG8: 0.056 | DH8: 0.1251 | DI8: 0.0571 | DJ8: 0.06659609 | DK8: 0.19399564 | DL8: 0.032435743 | DM8: 0.048 | DN8: 0.1251 | DO8: 0.0435 | DP8: 0.094023853 | DQ8: 0.17308476 | DR8: 0.035685812 | DS8: 0.06 | DT8: 0.1247 | DU8: 0.057 | DV8: 0.093354898 | DW8: 0.15601191 | DX8: 0.035641848 | DY8: 0.05 | DZ8: 0.1247 | EA8: 0.0383 | EB8: 0.090684186 | EC8: 0.15890146 | ED8: 0.033479495 | EE8: 0.051 | EF8: 0.1224 | EG8: 0.0582 | EH8: 0.085554944 | EI8: 0.16014163 | EJ8: 0.037387951 | EK8: 0.046 | EL8: 0.1209 | EM8: 0.0584 | EN8: 0.070102598 | EO8: 0.15854953 | EP8: 0.038812628 | EQ8: -0.041 | ER8: 0.1189 | ES8: 0.0459 | ET8: 0.070392861 | EU8: 0.16584227 | EV8: 0.034503103 | EW8: -0.036 | EX8: 0.1175 | EY8: 0.042 | EZ8: 0.06524467 | FA8: 0.16503957 | FB8: 0.03306708 | FC8: -0.003 | FD8: 0.1202 | FE8: 0.0562 | FF8: 0.064938122 | FG8: 0.16209224 | FH8: 0.034697625 | FI8: 0.024 | FJ8: 0.1205 | FK8: 0.059 | FL8: 0.067221619 | FM8: 0.1718153 | FN8: 0.032820995 | FO8: 0.103 | FP8: 0.1202 | FQ8: 0.0632 | FR8: 0.048919222 | FS8: 0.14381526 | FT8: 0.03613568 | FU8: 0.094 | FV8: 0.121 | FW8: 0.0691 | FX8: 0.046996673 | FY8: 0.16553527 | FZ8: 0.036180577 | GA8: 0.076 | GB8: 0.1216 | GC8: 0.0573 | GD8: 0.038601894 | GE8: 0.14663052 | GF8: 0.036109844 | GG8: 0.059 | GH8: 0.1215 | GI8: 0.0556 | GJ8: 0.029025729 | GK8: 0.15708413 | GL8: 0.03376416 | GM8: 0.049 | GN8: 0.1227 | GO8: 0.0791 | GP8: 0.052518491 | GQ8: 0.14937276 | GR8: 0.029296107 | GS8: 0.046 | GT8: 0.1241 | GU8: 0.0918 | GV8: 0.042240872 | GW8: 0.143508 | GX8: 0.03219609 | GY8: 0.049 | GZ8: 0.1267 | HA8: 0.0906 | HB8: 0.039390872 | HC8: 0.14771189 | HD8: 0.031471051 | HE8: 0.054 | HF8: 0.1309 | HG8: 0.0919 | HH8: 0.040923153 | HI8: 0.15428771 | HJ8: 0.025666807 | HK8: 0.055 | HL8: 0.1331 | HM8: 0.0788 | HN8: 0.046201258 | HO8: 0.13488828 | HP8: 0.02770808 | HQ8: 0.06 | HR8: 0.1398 | HS8: 0.0678 | HT8: 0.098691491 | HU8: 0.13565627 | HV8: 0.029241739 | HW8: 0.056 | HX8: 0.1463 | HY8: 0.0663 | HZ8: 0.067311488 | IA8: 0.1331656 | IB8: 0.031509782 | IC8: 0.049 | ID8: 0.1628 | IE8: 0.057 | IF8: 0.078825671 | IG8: 0.17343088 | IH8: 0.037880643 | II8: 0.046 | IJ8: 0.1685 | IK8: 0.0622 | IL8: 0.090061011 | IM8: 0.13189568 | IN8: 0.038040221 | IO8: 0.04 | IP8: 0.1691 | IQ8: 0.0356 | IR8: 0.095002862 | IS8: 0.1415614 | IT8: 0.038540623 | IU8: 0.047 | IV8: 0.1689 | IW8: 0.0299 | IX8: 0.10035976 | IY8: 0.17190224 | IZ8: 0.034405716 | JA8: 0.049 | JB8: 0.1577 | JC8: 0.0362 | JD8: 0.18768521 | JE8: 0.13024372 | JF8: 0.053187505 | JG8: 0.05 | JH8: 0.1528 | JI8: 0.0382 | JJ8: 0.11109098 | JK8: 0.1179198 | JL8: 0.040090858 | JM8: 0.049 | JN8: 0.1507 | JO8: 0.0458 | JP8: 0.10891076 | JQ8: 0.1172414 | JR8: 0.045792873 | JS8: 0.05 | JT8: 0.1481 | JU8: 0.0449 | JV8: 0.10966313 | JW8: 0.11891256 | JX8: 0.055791948
A9: 5 | B9: Absa Bank Kenya | C9: 0.052 | D9: 0.1691 | E9: 0.0627 | F9: 0.038103839 | G9: 0.52865679 | H9: 0.038067107 | I9: 0.06 | J9: 0.1636 | K9: 0.0739 | L9: 0.032196493 | M9: 0.51027995 | N9: 0.040274003 | O9: 0.05 | P9: 0.1599 | Q9: 0.0602 | R9: 0.035040031 | S9: 0.51575768 | T9: 0.038729202 | U9: 0.057 | V9: 0.1546 | W9: 0.0631 | X9: 0.033980753 | Y9: 0.52896178 | Z9: 0.038041927 | AA9: 0.056 | AB9: 0.1606 | AC9: 0.0703 | AD9: 0.033901174 | AE9: 0.52629811 | AF9: 0.039514012 | AG9: 0.061 | AH9: 0.1682 | AI9: 0.0597 | AJ9: 0.03932776 | AK9: 0.53488734 | AL9: 0.03819356 | AM9: 0.05 | AN9: 0.183 | AO9: 0.0801 | AP9: 0.030376412 | AQ9: 0.53026031 | AR9: 0.035955945 | AS9: 0.038 | AT9: 0.1787 | AU9: 0.0645 | AV9: 0.040269707 | AW9: 0.51930096 | AX9: 0.038523037 | AY9: 0.038 | AZ9: 0.1818 | BA9: 0.058 | BB9: 0.040995473 | BC9: 0.51755107 | BD9: 0.032871328 | BE9: 0.044 | BF9: 0.1386 | BG9: 0.0634 | BH9: 0.046683675 | BI9: 0.51484825 | BJ9: 0.046031156 | BK9: 0.042 | BL9: 0.1366 | BM9: 0.0635 | BN9: 0.049538249 | BO9: 0.53939573 | BP9: 0.028408401 | BQ9: 0.054 | BR9: 0.1361 | BS9: 0.1028 | BT9: 0.049381487 | BU9: 0.56442424 | BV9: 0.025359819 | BW9: 0.033 | BX9: 0.1366 | BY9: 0.0921 | BZ9: 0.050802085 | CA9: 0.57132269 | CB9: 0.025682545 | CC9: 0.032 | CD9: 0.1369 | CE9: 0.0706 | CF9: 0.050569477 | CG9: 0.56207039 | CH9: 0.025325797 | CI9: 0.038 | CJ9: 0.1364 | CK9: 0.045 | CL9: 0.052648873 | CM9: 0.55943392 | CN9: 0.025149938 | CO9: 0.052 | CP9: 0.1349 | CQ9: 0.0418 | CR9: 0.053173856 | CS9: 0.58220979 | CT9: 0.025367168 | CU9: 0.061 | CV9: 0.1322 | CW9: 0.0428 | CX9: 0.05844344 | CY9: 0.55886479 | CZ9: 0.024513786 | DA9: 0.053 | DB9: 0.1266 | DC9: 0.057 | DD9: 0.060632845 | DE9: 0.56378617 | DF9: 0.033155691 | DG9: 0.056 | DH9: 0.1251 | DI9: 0.0571 | DJ9: 0.057517939 | DK9: 0.54656329 | DL9: 0.023931614 | DM9: 0.048 | DN9: 0.1251 | DO9: 0.0435 | DP9: 0.064382445 | DQ9: 0.54629153 | DR9: 0.02146836 | DS9: 0.06 | DT9: 0.1247 | DU9: 0.057 | DV9: 0.063596535 | DW9: 0.51797998 | DX9: 0.022131739 | DY9: 0.05 | DZ9: 0.1247 | EA9: 0.0383 | EB9: 0.053392293 | EC9: 0.51232535 | ED9: 0.0208122 | EE9: 0.051 | EF9: 0.1224 | EG9: 0.0582 | EH9: 0.05304483 | EI9: 0.5155539 | EJ9: 0 | EK9: 0.046 | EL9: 0.1209 | EM9: 0.0584 | EN9: 0.068632606 | EO9: 0.47567404 | EP9: 0.019408116 | EQ9: -0.041 | ER9: 0.1189 | ES9: 0.0459 | ET9: 0.067303992 | EU9: 0.48875468 | EV9: 0.0020230382 | EW9: -0.036 | EX9: 0.1175 | EY9: 0.042 | EZ9: 0.063946093 | FA9: 0.4927631 | FB9: 0.0056968154 | FC9: -0.003 | FD9: 0.1202 | FE9: 0.0562 | FF9: 0.065614331 | FG9: 0.48411089 | FH9: 0.0098232123 | FI9: 0.024 | FJ9: 0.1205 | FK9: 0.059 | FL9: 0.063699793 | FM9: 0.46016314 | FN9: 0.023643296 | FO9: 0.103 | FP9: 0.1202 | FQ9: 0.0632 | FR9: 0.067876038 | FS9: 0.44950093 | FT9: 0.027040217 | FU9: 0.094 | FV9: 0.121 | FW9: 0.0691 | FX9: 0.069875001 | FY9: 0.44501379 | FZ9: 0.026117109 | GA9: 0.076 | GB9: 0.1216 | GC9: 0.0573 | GD9: 0.068857847 | GE9: 0.45611909 | GF9: 0.025213555 | GG9: 0.059 | GH9: 0.1215 | GI9: 0.0556 | GJ9: 0.065949752 | GK9: 0.45558452 | GL9: 0.025412043 | GM9: 0.049 | GN9: 0.1227 | GO9: 0.0791 | GP9: 0.062243391 | GQ9: 0.42890334 | GR9: 0.027165922 | GS9: 0.046 | GT9: 0.1241 | GU9: 0.0918 | GV9: 0.056884269 | GW9: 0.40216577 | GX9: 0.02975333 | GY9: 0.049 | GZ9: 0.1267 | HA9: 0.0906 | HB9: 0.058827993 | HC9: 0.41120598 | HD9: 0.030612193 | HE9: 0.054 | HF9: 0.1309 | HG9: 0.0919 | HH9: 0.07908864 | HI9: 0.372397 | HJ9: 0.033286073 | HK9: 0.055 | HL9: 0.1331 | HM9: 0.0788 | HN9: 0.079690281 | HO9: 0.37782725 | HP9: 0.031527449 | HQ9: 0.06 | HR9: 0.1398 | HS9: 0.0678 | HT9: 0.080934381 | HU9: 0.39487968 | HV9: 0.031159682 | HW9: 0.056 | HX9: 0.1463 | HY9: 0.0663 | HZ9: 0.080580895 | IA9: 0.40335248 | IB9: 0.030827195 | IC9: 0.049 | ID9: 0.1628 | IE9: 0.057 | IF9: 0.09093433 | IG9: 0.34603637 | IH9: 0.043918776 | II9: 0.046 | IJ9: 0.1685 | IK9: 0.0622 | IL9: 0.093688589 | IM9: 0.36422822 | IN9: 0.040251511 | IO9: 0.04 | IP9: 0.1691 | IQ9: 0.0356 | IR9: 0.10242028 | IS9: 0.38560151 | IT9: 0.036641111 | IU9: 0.047 | IV9: 0.1689 | IW9: 0.0299 | IX9: 0.10238959 | IY9: 0.38411414 | IZ9: 0.038265147 | JA9: 0.049 | JB9: 0.1577 | JC9: 0.0362 | JD9: 0.10526973 | JE9: 0.36310462 | JF9: 0.044132875 | JG9: 0.05 | JH9: 0.1528 | JI9: 0.0382 | JJ9: 0.10559877 | JK9: 0.37658668 | JL9: 0.041252564 | JM9: 0.049 | JN9: 0.1507 | JO9: 0.0458 | JP9: 0.10451268 | JQ9: 0.39032334 | JR9: 0.038731484 | JS9: 0.05 | JT9: 0.1481 | JU9: 0.0449 | JV9: 0.090584839 | JW9: 0.37882609 | JX9: 0.04017011
A10: 6 | B10: Stanbic Bank | C10: 0.052 | D10: 0.1691 | E10: 0.0627 | F10: 0.021255656 | G10: 0.51904229 | H10: 0.038951559 | I10: 0.06 | J10: 0.1636 | K10: 0.0739 | L10: 0.012267936 | M10: 0.50160014 | N10: 0.039711495 | O10: 0.05 | P10: 0.1599 | Q10: 0.0602 | R10: 0.033092824 | S10: 0.49847088 | T10: 0.032032263 | U10: 0.057 | V10: 0.1546 | W10: 0.0631 | X10: 0.034378891 | Y10: 0.56022453 | Z10: 0.027267188 | AA10: 0.056 | AB10: 0.1606 | AC10: 0.0703 | AD10: 0.032924261 | AE10: 0.59958418 | AF10: 0.019397298 | AG10: 0.061 | AH10: 0.1682 | AI10: 0.0597 | AJ10: 0.032046141 | AK10: 0.59030261 | AL10: 0.01934098 | AM10: 0.05 | AN10: 0.183 | AO10: 0.0801 | AP10: 0.03943801 | AQ10: 0.50591733 | AR10: 0.02539452 | AS10: 0.038 | AT10: 0.1787 | AU10: 0.0645 | AV10: 0.04115104 | AW10: 0.48772163 | AX10: 0.023355536 | AY10: 0.038 | AZ10: 0.1818 | BA10: 0.058 | BB10: 0.04378028 | BC10: 0.51485647 | BD10: 0.023554407 | BE10: 0.044 | BF10: 0.1386 | BG10: 0.0634 | BH10: 0.046162351 | BI10: 0.57674939 | BJ10: 0.021265017 | BK10: 0.042 | BL10: 0.1366 | BM10: 0.0635 | BN10: 0.048052143 | BO10: 0.50261322 | BP10: 0.021936537 | BQ10: 0.054 | BR10: 0.1361 | BS10: 0.1028 | BT10: 0.047536934 | BU10: 0.56663304 | BV10: 0.020616008 | BW10: 0.033 | BX10: 0.1366 | BY10: 0.0921 | BZ10: 0.042852431 | CA10: 0.54079311 | CB10: 0.016097209 | CC10: 0.032 | CD10: 0.1369 | CE10: 0.0706 | CF10: 0.061214872 | CG10: 0.5242787 | CH10: 0.019486055 | CI10: 0.038 | CJ10: 0.1364 | CK10: 0.045 | CL10: 0.062448864 | CM10: 0.5516432 | CN10: 0.019532327 | CO10: 0.052 | CP10: 0.1349 | CQ10: 0.0418 | CR10: 0.061931022 | CS10: 0.49388389 | CT10: 0.031551997 | CU10: 0.061 | CV10: 0.1322 | CW10: 0.0428 | CX10: 0.057773053 | CY10: 0.47808192 | CZ10: 0.027426248 | DA10: 0.053 | DB10: 0.1266 | DC10: 0.057 | DD10: 0.054421144 | DE10: 0.50099357 | DF10: 0.034014831 | DG10: 0.056 | DH10: 0.1251 | DI10: 0.0571 | DJ10: 0.086329554 | DK10: 0.50195626 | DL10: 0.023737649 | DM10: 0.048 | DN10: 0.1251 | DO10: 0.0435 | DP10: 0.085509165 | DQ10: 0.43570287 | DR10: 0.03249934 | DS10: 0.06 | DT10: 0.1247 | DU10: 0.057 | DV10: 0.080363254 | DW10: 0.47960913 | DX10: 0.027089815 | DY10: 0.05 | DZ10: 0.1247 | EA10: 0.0383 | EB10: 0.082825751 | EC10: 0.54406436 | ED10: 0.023667806 | EE10: 0.051 | EF10: 0.1224 | EG10: 0.0582 | EH10: 0.090731362 | EI10: 0.53903147 | EJ10: 0.021692864 | EK10: 0.046 | EL10: 0.1209 | EM10: 0.0584 | EN10: 0.091679775 | EO10: 0.48862189 | EP10: 0.020313194 | EQ10: -0.041 | ER10: 0.1189 | ES10: 0.0459 | ET10: 0.090617807 | EU10: 0.46456849 | EV10: 0.015502641 | EW10: -0.036 | EX10: 0.1175 | EY10: 0.042 | EZ10: 0.091773839 | FA10: 0.48086172 | FB10: 0.015593645 | FC10: -0.003 | FD10: 0.1202 | FE10: 0.0562 | FF10: 0.11076257 | FG10: 0.52014163 | FH10: 0.017114583 | FI10: 0.024 | FJ10: 0.1205 | FK10: 0.059 | FL10: 0.11483654 | FM10: 0.46650774 | FN10: 0.023736752 | FO10: 0.103 | FP10: 0.1202 | FQ10: 0.0632 | FR10: 0.095153411 | FS10: 0.50422162 | FT10: 0.021202069 | FU10: 0.094 | FV10: 0.121 | FW10: 0.0691 | FX10: 0.092260273 | FY10: 0.51122854 | FZ10: 0.022248847 | GA10: 0.076 | GB10: 0.1216 | GC10: 0.0573 | GD10: 0.089619218 | GE10: 0.51898274 | GF10: 0.022187933 | GG10: 0.059 | GH10: 0.1215 | GI10: 0.0556 | GJ10: 0.08744815 | GK10: 0.49564875 | GL10: 0.025962226 | GM10: 0.049 | GN10: 0.1227 | GO10: 0.0791 | GP10: 0.082338254 | GQ10: 0.48308284 | GR10: 0.029297209 | GS10: 0.046 | GT10: 0.1241 | GU10: 0.0918 | GV10: 0.079479968 | GW10: 0.4541808 | GX10: 0.02700536 | GY10: 0.049 | GZ10: 0.1267 | HA10: 0.0906 | HB10: 0.087940029 | HC10: 0.46583438 | HD10: 0.025619363 | HE10: 0.054 | HF10: 0.1309 | HG10: 0.0919 | HH10: 0.090800207 | HI10: 0.40478907 | HJ10: 0.056219969 | HK10: 0.055 | HL10: 0.1331 | HM10: 0.0788 | HN10: 0.072127166 | HO10: 0.4286554 | HP10: 0.035296539 | HQ10: 0.06 | HR10: 0.1398 | HS10: 0.0678 | HT10: 0.070236812 | HU10: 0.34636509 | HV10: 0.030764962 | HW10: 0.056 | HX10: 0.1463 | HY10: 0.0663 | HZ10: 0.073113642 | IA10: 0.42374787 | IB10: 0.028384116 | IC10: 0.049 | ID10: 0.1628 | IE10: 0.057 | IF10: 0.067894536 | IG10: 0.35667466 | IH10: 0.033978647 | II10: 0.046 | IJ10: 0.1685 | IK10: 0.0622 | IL10: 0.072461436 | IM10: 0.40373905 | IN10: 0.030312483 | IO10: 0.04 | IP10: 0.1691 | IQ10: 0.0356 | IR10: 0.079132732 | IS10: 0.42941958 | IT10: 0.029649805 | IU10: 0.047 | IV10: 0.1689 | IW10: 0.0299 | IX10: 0.06790174 | IY10: 0.43352391 | IZ10: 0.030506717 | JA10: 0.049 | JB10: 0.1577 | JC10: 0.0362 | JD10: 0.063596227 | JE10: 0.48205155 | JF10: 0.036488459 | JG10: 0.05 | JH10: 0.1528 | JI10: 0.0382 | JJ10: 0.06895431 | JK10: 0.47466601 | JL10: 0.036943962 | JM10: 0.049 | JN10: 0.1507 | JO10: 0.0458 | JP10: 0.060125185 | JQ10: 0.45635151 | JR10: 0.027157396 | JS10: 0.05 | JT10: 0.1481 | JU10: 0.0449 | JV10: 0.056981394 | JW10: 0.45907583 | JX10: 0.027649597
A11: 7 | B11: Chase Bank | C11: 0.052 | D11: 0.1691 | E11: 0.0627 | F11: 0.025240983 | G11: 0.50051175 | H11: 0.021067733 | I11: 0.06 | J11: 0.1636 | K11: 0.0739 | L11: 0.02620056 | M11: 0.4900459 | N11: 0.025511105 | O11: 0.05 | P11: 0.1599 | Q11: 0.0602 | R11: 0.040687918 | S11: 0.5529911 | T11: 0.025224122 | U11: 0.057 | V11: 0.1546 | W11: 0.0631 | X11: 0.042175276 | Y11: 0.52540315 | Z11: 0.025283942 | AA11: 0.056 | AB11: 0.1606 | AC11: 0.0703 | AD11: 0.044058319 | AE11: 0.51178692 | AF11: 0.02468733 | AG11: 0.061 | AH11: 0.1682 | AI11: 0.0597 | AJ11: 0.039361257 | AK11: 0.5452865 | AL11: 0.023661921 | AM11: 0.05 | AN11: 0.183 | AO11: 0.0801 | AP11: 0.092405475 | AQ11: 0.86812519 | AR11: -0.0059528436 | AS11: 0.038 | AT11: 0.1787 | AU11: 0.0645 | AV11: NA | AW11: NA | AX11: NA | AY11: 0.038 | AZ11: 0.1818 | BA11: 0.058 | BB11: NA | BC11: NA | BD11: NA | BE11: 0.044 | BF11: 0.1386 | BG11: 0.0634 | BH11: NA | BI11: NA | BJ11: NA | BK11: 0.042 | BL11: 0.1366 | BM11: 0.0635 | BN11: NA | BO11: NA | BP11: NA | BQ11: 0.054 | BR11: 0.1361 | BS11: 0.1028 | BT11: NA | BU11: NA | BV11: NA | BW11: 0.033 | BX11: 0.1366 | BY11: 0.0921 | BZ11: NA | CA11: NA | CB11: NA | CC11: 0.032 | CD11: 0.1369 | CE11: 0.0706 | CF11: NA | CG11: NA | CH11: NA | CI11: 0.038 | CJ11: 0.1364 | CK11: 0.045 | CL11: NA | CM11: NA | CN11: NA | CO11: 0.052 | CP11: 0.1349 | CQ11: 0.0418 | CR11: NA | CS11: NA | CT11: NA | CU11: 0.061 | CV11: 0.1322 | CW11: 0.0428 | CX11: NA | CY11: NA | CZ11: NA | DA11: 0.053 | DB11: 0.1266 | DC11: 0.057 | DD11: NA | DE11: NA | DF11: NA | DG11: 0.056 | DH11: 0.1251 | DI11: 0.0571 | DJ11: NA | DK11: NA | DL11: NA | DM11: 0.048 | DN11: 0.1251 | DO11: 0.0435 | DP11: NA | DQ11: NA | DR11: NA | DS11: 0.06 | DT11: 0.1247 | DU11: 0.057 | DV11: NA | DW11: NA | DX11: NA | DY11: 0.05 | DZ11: 0.1247 | EA11: 0.0383 | EB11: NA | EC11: NA | ED11: NA | EE11: 0.051 | EF11: 0.1224 | EG11: 0.0582 | EH11: NA | EI11: NA | EJ11: NA | EK11: 0.046 | EL11: 0.1209 | EM11: 0.0584 | EN11: NA | EO11: NA | EP11: NA | EQ11: -0.041 | ER11: 0.1189 | ES11: 0.0459 | ET11: NA | EU11: NA | EV11: NA | EW11: -0.036 | EX11: 0.1175 | EY11: 0.042 | EZ11: NA | FA11: NA | FB11: NA | FC11: -0.003 | FD11: 0.1202 | FE11: 0.0562 | FF11: NA | FG11: NA | FH11: NA | FI11: 0.024 | FJ11: 0.1205 | FK11: 0.059 | FL11: NA | FM11: NA | FN11: NA | FO11: 0.103 | FP11: 0.1202 | FQ11: 0.0632 | FR11: NA | FS11: NA | FT11: NA | FU11: 0.094 | FV11: 0.121 | FW11: 0.0691 | FX11: NA | FY11: NA | FZ11: NA | GA11: 0.076 | GB11: 0.1216 | GC11: 0.0573 | GD11: NA | GE11: NA | GF11: NA | GG11: 0.059 | GH11: 0.1215 | GI11: 0.0556 | GJ11: NA | GK11: NA | GL11: NA | GM11: 0.049 | GN11: 0.1227 | GO11: 0.0791 | GP11: NA | GQ11: NA | GR11: NA | GS11: 0.046 | GT11: 0.1241 | GU11: 0.0918 | GV11: NA | GW11: NA | GX11: NA | GY11: 0.049 | GZ11: 0.1267 | HA11: 0.0906 | HB11: NA | HC11: NA | HD11: NA | HE11: 0.054 | HF11: 0.1309 | HG11: 0.0919 | HH11: NA | HI11: NA | HJ11: NA | HK11: 0.055 | HL11: 0.1331 | HM11: 0.0788 | HN11: NA | HO11: NA | HP11: NA | HQ11: 0.06 | HR11: 0.1398 | HS11: 0.0678 | HT11: NA | HU11: NA | HV11: NA | HW11: 0.056 | HX11: 0.1463 | HY11: 0.0663 | HZ11: NA | IA11: NA | IB11: NA | IC11: 0.049 | ID11: 0.1628 | IE11: 0.057 | IF11: NA | IG11: NA | IH11: NA | II11: 0.046 | IJ11: 0.1685 | IK11: 0.0622 | IL11: NA | IM11: NA | IN11: NA | IO11: 0.04 | IP11: 0.1691 | IQ11: 0.0356 | IR11: NA | IS11: NA | IT11: NA | IU11: 0.047 | IV11: 0.1689 | IW11: 0.0299 | IX11: NA | IY11: NA | IZ11: NA | JA11: 0.049 | JB11: 0.1577 | JC11: 0.0362 | JD11: NA | JE11: NA | JF11: NA | JG11: 0.05 | JH11: 0.1528 | JI11: 0.0382 | JJ11: NA | JK11: NA | JL11: NA | JM11: 0.049 | JN11: 0.1507 | JO11: 0.0458 | JP11: NA | JQ11: NA | JR11: NA | JS11: 0.05 | JT11: 0.1481 | JU11: 0.0449 | JV11: NA | JW11: NA | JX11: NA
A12: 8 | B12: Citibank | C12: 0.052 | D12: 0.1691 | E12: 0.0627 | F12: 0.0060500984 | G12: 0.35193766 | H12: 0.039438919 | I12: 0.06 | J12: 0.1636 | K12: 0.0739 | L12: 0.0045586433 | M12: 0.40238331 | N12: 0.032869648 | O12: 0.05 | P12: 0.1599 | Q12: 0.0602 | R12: 0.036996585 | S12: 0.42933701 | T12: 0.03243568 | U12: 0.057 | V12: 0.1546 | W12: 0.0631 | X12: 0.051009874 | Y12: 0.30643599 | Z12: 0.042666905 | AA12: 0.056 | AB12: 0.1606 | AC12: 0.0703 | AD12: 0.033123348 | AE12: 0.3490164 | AF12: 0.032547667 | AG12: 0.061 | AH12: 0.1682 | AI12: 0.0597 | AJ12: 0.031013004 | AK12: 0.34585148 | AL12: 0.035100484 | AM12: 0.05 | AN12: 0.183 | AO12: 0.0801 | AP12: 0.054840166 | AQ12: 0.32029579 | AR12: 0.040597548 | AS12: 0.038 | AT12: 0.1787 | AU12: 0.0645 | AV12: 0.048539079 | AW12: 0.46338928 | AX12: 0.030484526 | AY12: 0.038 | AZ12: 0.1818 | BA12: 0.058 | BB12: 0.038900672 | BC12: 0.35070412 | BD12: 0.033040598 | BE12: 0.044 | BF12: 0.1386 | BG12: 0.0634 | BH12: 0.034128611 | BI12: 0.39106697 | BJ12: 0.02862068 | BK12: 0.042 | BL12: 0.1366 | BM12: 0.0635 | BN12: 0.018842164 | BO12: 0.33895317 | BP12: 0.035850777 | BQ12: 0.054 | BR12: 0.1361 | BS12: 0.1028 | BT12: 0.048479409 | BU12: 0.43109224 | BV12: 0.028404925 | BW12: 0.033 | BX12: 0.1366 | BY12: 0.0921 | BZ12: 0.046123527 | CA12: 0.33587879 | CB12: 0.042951928 | CC12: 0.032 | CD12: 0.1369 | CE12: 0.0706 | CF12: 0.044319377 | CG12: 0.32766685 | CH12: 0.039707028 | CI12: 0.038 | CJ12: 0.1364 | CK12: 0.045 | CL12: 0.035499899 | CM12: 0.32669581 | CN12: 0.038802384 | CO12: 0.052 | CP12: 0.1349 | CQ12: 0.0418 | CR12: 0.015949684 | CS12: 0.31645605 | CT12: 0.026882866 | CU12: 0.061 | CV12: 0.1322 | CW12: 0.0428 | CX12: 0.014017693 | CY12: 0.33671588 | CZ12: 0.034479276 | DA12: 0.053 | DB12: 0.1266 | DC12: 0.057 | DD12: 0.014250816 | DE12: 0.33508204 | DF12: 0.058281667 | DG12: 0.056 | DH12: 0.1251 | DI12: 0.0571 | DJ12: 0.01595735 | DK12: 0.3661205 | DL12: 0.034391273 | DM12: 0.048 | DN12: 0.1251 | DO12: 0.0435 | DP12: 0.016237889 | DQ12: 0.37014591 | DR12: 0.044987731 | DS12: 0.06 | DT12: 0.1247 | DU12: 0.057 | DV12: 0.01620172 | DW12: 0.38499266 | DX12: 0.035427577 | DY12: 0.05 | DZ12: 0.1247 | EA12: 0.0383 | EB12: 0.018776861 | EC12: 0.38498059 | ED12: 0.035943844 | EE12: 0.051 | EF12: 0.1224 | EG12: 0.0582 | EH12: 0.025031368 | EI12: 0.38476123 | EJ12: 0.03219033 | EK12: 0.046 | EL12: 0.1209 | EM12: 0.0584 | EN12: 0.021749031 | EO12: 0.35745588 | EP12: 0.038948661 | EQ12: -0.041 | ER12: 0.1189 | ES12: 0.0459 | ET12: 0.02425567 | EU12: 0.37007058 | EV12: 0.034591976 | EW12: -0.036 | EX12: 0.1175 | EY12: 0.042 | EZ12: 0.02226798 | FA12: 0.38087383 | FB12: 0 | FC12: -0.003 | FD12: 0.1202 | FE12: 0.0562 | FF12: 0.022199034 | FG12: 0.33614421 | FH12: 0.031168657 | FI12: 0.024 | FJ12: 0.1205 | FK12: 0.059 | FL12: 0.016869609 | FM12: 0.37660801 | FN12: 0.033270352 | FO12: 0.103 | FP12: 0.1202 | FQ12: 0.0632 | FR12: 0.017828566 | FS12: 0.38977698 | FT12: 0.031210087 | FU12: 0.094 | FV12: 0.121 | FW12: 0.0691 | FX12: 0.017115981 | FY12: 0.38052962 | FZ12: 0.031271851 | GA12: 0.076 | GB12: 0.1216 | GC12: 0.0573 | GD12: 0.01372247 | GE12: 0.34807052 | GF12: 0.03001605 | GG12: 0.059 | GH12: 0.1215 | GI12: 0.0556 | GJ12: 0.013762914 | GK12: 0.35052142 | GL12: 0.035908465 | GM12: 0.049 | GN12: 0.1227 | GO12: 0.0791 | GP12: 0.016774356 | GQ12: 0.30388712 | GR12: 0.039473693 | GS12: 0.046 | GT12: 0.1241 | GU12: 0.0918 | GV12: 0.019718307 | GW12: 0.28562364 | GX12: 0.043723501 | GY12: 0.049 | GZ12: 0.1267 | HA12: 0.0906 | HB12: 0.024586672 | HC12: 0.28936363 | HD12: 0.043534494 | HE12: 0.054 | HF12: 0.1309 | HG12: 0.0919 | HH12: 0.031139226 | HI12: 0.30505036 | HJ12: 0.052115045 | HK12: 0.055 | HL12: 0.1331 | HM12: 0.0788 | HN12: 0.027288505 | HO12: 0.275385 | HP12: 0.063583606 | HQ12: 0.06 | HR12: 0.1398 | HS12: 0.0678 | HT12: 0.027097875 | HU12: 0.28174677 | HV12: 0.060239587 | HW12: 0.056 | HX12: 0.1463 | HY12: 0.0663 | HZ12: 0.036712597 | IA12: 0.28205235 | IB12: 0.057282257 | IC12: 0.049 | ID12: 0.1628 | IE12: 0.057 | IF12: 0.031075083 | IG12: 0.25044579 | IH12: 0.080336488 | II12: 0.046 | IJ12: 0.1685 | IK12: 0.0622 | IL12: 0.031629359 | IM12: 0.27257648 | IN12: 0.067829953 | IO12: 0.04 | IP12: 0.1691 | IQ12: 0.0356 | IR12: 0.031984725 | IS12: 0.27958169 | IT12: 0.069182113 | IU12: 0.047 | IV12: 0.1689 | IW12: 0.0299 | IX12: 0.032497449 | IY12: 0.29247902 | IZ12: 0.064774631 | JA12: 0.049 | JB12: 0.1577 | JC12: 0.0362 | JD12: 0.034799886 | JE12: 0.30481861 | JF12: 0.073166882 | JG12: 0.05 | JH12: 0.1528 | JI12: 0.0382 | JJ12: 0.040896731 | JK12: 0.30756849 | JL12: 0.04649152 | JM12: 0.049 | JN12: 0.1507 | JO12: 0.0458 | JP12: 0.037001893 | JQ12: 0.33155584 | JR12: 0.043491942 | JS12: 0.05 | JT12: 0.1481 | JU12: 0.0449 | JV12: 0.035167096 | JW12: 0.36945303 | JX12: 0.039215627
A13: 9 | B13: Commercial Bank of Africa | C13: 0.052 | D13: 0.1691 | E13: 0.0627 | F13: 0.033730079 | G13: 0.49028313 | H13: 0.024343904 | I13: 0.06 | J13: 0.1636 | K13: 0.0739 | L13: 0.030680544 | M13: 0.47154327 | N13: 0.024083989 | O13: 0.05 | P13: 0.1599 | Q13: 0.0602 | R13: 0.03312438 | S13: 0.48156422 | T13: 0.02510589 | U13: 0.057 | V13: 0.1546 | W13: 0.0631 | X13: 0.044465976 | Y13: 0.44478976 | Z13: 0.019171989 | AA13: 0.056 | AB13: 0.1606 | AC13: 0.0703 | AD13: 0.046290784 | AE13: 0.43476316 | AF13: 0.021501009 | AG13: 0.061 | AH13: 0.1682 | AI13: 0.0597 | AJ13: 0.039017427 | AK13: 0.42869251 | AL13: 0.023930074 | AM13: 0.05 | AN13: 0.183 | AO13: 0.0801 | AP13: 0.036887527 | AQ13: 0.42422482 | AR13: 0.024661213 | AS13: 0.038 | AT13: 0.1787 | AU13: 0.0645 | AV13: 0.069980232 | AW13: 0.37373911 | AX13: 0.022128211 | AY13: 0.038 | AZ13: 0.1818 | BA13: 0.058 | BB13: 0.076698648 | BC13: 0.36697353 | BD13: 0.02339494 | BE13: 0.044 | BF13: 0.1386 | BG13: 0.0634 | BH13: 0.082942435 | BI13: 0.37158207 | BJ13: 0.024822051 | BK13: 0.042 | BL13: 0.1366 | BM13: 0.0635 | BN13: 0.038021398 | BO13: 0.37002554 | BP13: 0.03220974 | BQ13: 0.054 | BR13: 0.1361 | BS13: 0.1028 | BT13: 0.064403048 | BU13: 0.40379313 | BV13: 0.028259096 | BW13: 0.033 | BX13: 0.1366 | BY13: 0.0921 | BZ13: 0.063436596 | CA13: 0.42468993 | CB13: 0.02514716 | CC13: 0.032 | CD13: 0.1369 | CE13: 0.0706 | CF13: 0.068965185 | CG13: 0.43621625 | CH13: 0.024528444 | CI13: 0.038 | CJ13: 0.1364 | CK13: 0.045 | CL13: 0.056792742 | CM13: 0.46506056 | CN13: 0.025824493 | CO13: 0.052 | CP13: 0.1349 | CQ13: 0.0418 | CR13: 0.067244965 | CS13: 0.53250578 | CT13: 0.018933462 | CU13: 0.061 | CV13: 0.1322 | CW13: 0.0428 | CX13: 0.064925769 | CY13: 0.45223296 | CZ13: 0.024118094 | DA13: 0.053 | DB13: 0.1266 | DC13: 0.057 | DD13: 0.071260583 | DE13: 0.4677188 | DF13: 0.034848524 | DG13: 0.056 | DH13: 0.1251 | DI13: 0.0571 | DJ13: 0.060640957 | DK13: 0.46766325 | DL13: 0.02625214 | DM13: 0.048 | DN13: 0.1251 | DO13: 0.0435 | DP13: 0.062143521 | DQ13: 0.54494218 | DR13: 0.021319183 | DS13: 0.06 | DT13: 0.1247 | DU13: 0.057 | DV13: 0.065774757 | DW13: 0.49378314 | DX13: 0.023459501 | DY13: 0.05 | DZ13: 0.1247 | EA13: 0.0383 | EB13: 0.077252227 | EC13: 0.54553796 | ED13: 0.025799714 | EE13: 0.051 | EF13: 0.1224 | EG13: 0.0582 | EH13: NA | EI13: NA | EJ13: NA | EK13: 0.046 | EL13: 0.1209 | EM13: 0.0584 | EN13: NA | EO13: NA | EP13: NA | EQ13: -0.041 | ER13: 0.1189 | ES13: 0.0459 | ET13: NA | EU13: NA | EV13: NA | EW13: -0.036 | EX13: 0.1175 | EY13: 0.042 | EZ13: NA | FA13: NA | FB13: NA | FC13: -0.003 | FD13: 0.1202 | FE13: 0.0562 | FF13: NA | FG13: NA | FH13: NA | FI13: 0.024 | FJ13: 0.1205 | FK13: 0.059 | FL13: NA | FM13: NA | FN13: NA | FO13: 0.103 | FP13: 0.1202 | FQ13: 0.0632 | FR13: NA | FS13: NA | FT13: NA | FU13: 0.094 | FV13: 0.121 | FW13: 0.0691 | FX13: NA | FY13: NA | FZ13: NA | GA13: 0.076 | GB13: 0.1216 | GC13: 0.0573 | GD13: NA | GE13: NA | GF13: NA | GG13: 0.059 | GH13: 0.1215 | GI13: 0.0556 | GJ13: NA | GK13: NA | GL13: NA | GM13: 0.049 | GN13: 0.1227 | GO13: 0.0791 | GP13: NA | GQ13: NA | GR13: NA | GS13: 0.046 | GT13: 0.1241 | GU13: 0.0918 | GV13: NA | GW13: NA | GX13: NA | GY13: 0.049 | GZ13: 0.1267 | HA13: 0.0906 | HB13: NA | HC13: NA | HD13: NA | HE13: 0.054 | HF13: 0.1309 | HG13: 0.0919 | HH13: NA | HI13: NA | HJ13: NA | HK13: 0.055 | HL13: 0.1331 | HM13: 0.0788 | HN13: NA | HO13: NA | HP13: NA | HQ13: 0.06 | HR13: 0.1398 | HS13: 0.0678 | HT13: NA | HU13: NA | HV13: NA | HW13: 0.056 | HX13: 0.1463 | HY13: 0.0663 | HZ13: NA | IA13: NA | IB13: NA | IC13: 0.049 | ID13: 0.1628 | IE13: 0.057 | IF13: NA | IG13: NA | IH13: NA | II13: 0.046 | IJ13: 0.1685 | IK13: 0.0622 | IL13: NA | IM13: NA | IN13: NA | IO13: 0.04 | IP13: 0.1691 | IQ13: 0.0356 | IR13: NA | IS13: NA | IT13: NA | IU13: 0.047 | IV13: 0.1689 | IW13: 0.0299 | IX13: NA | IY13: NA | IZ13: NA | JA13: 0.049 | JB13: 0.1577 | JC13: 0.0362 | JD13: NA | JE13: NA | JF13: NA | JG13: 0.05 | JH13: 0.1528 | JI13: 0.0382 | JJ13: NA | JK13: NA | JL13: NA | JM13: 0.049 | JN13: 0.1507 | JO13: 0.0458 | JP13: NA | JQ13: NA | JR13: NA | JS13: 0.05 | JT13: 0.1481 | JU13: 0.0449 | JV13: NA | JW13: NA | JX13: NA
